Workbook
Name i_PROBLAM_art1: Tabla_PROBLAM_Artefactos1[]
Name i_PROBLAM_art2: Tabla_PROBLAM_Artefactos2[]
Name i_PROBLAM_art3: Tabla_PROBLAM_Artefactos3[]
Name i_PROBLAM_art4: Tabla_PROBLAM_Artefactos4[]
Name i_PROBLAM_art5: Tabla_PROBLAM_Artefactos5[]
Name i_PROBLAM_art6: Tabla_PROBLAM_Artefactos6[]
Name i_PROBLAM_pt1: problam!$B$3
Name i_PROBLAM_pt2: problam!$B$4
Name i_PROBLAM_pt3: problam!$B$5
Name i_PROBLAM_pt4: problam!$B$6
Name i_PROBLAM_pt5: problam!$B$7
Name i_PROBLAM_pt6: problam!$B$8
Name Indice_Aux_SinFecha: problam!$D$28:$D$28
Name Indice_Aux_Vacio: problam!$B$28
Name Indice_Plan_Actividad: OFFSET(INDEX(plan!$C$4:$C$52,1),0,0,plan!#REF!,1)
Name Indice_Plan_ExtensionPlazo: problam!$F$24
Name Indice_Plan_FechaFin: problam!$B$25
Name Indice_Plan_FechaInicio: problam!$B$24
Name Indice_Plan_InicioSemana: problam!$D$24
Name Indice_PROBLAM_Aux_Estado_Bloqueada: problam!$B$11
Name Indice_PROBLAM_Aux_Estado_Desarrollo: problam!$B$12
Name Indice_PROBLAM_Aux_Estado_Finalizada: problam!$B$13
Name Indice_PROBLAM_Aux_Estado_SinIniciar: problam!$B$14
Name Indice_PROBLAM_Aux_Estados: Tabla_PROBLAM_Aux_Estados[Estado]
Name Indice_PROBLAM_Estudiante1: problam!$B$17
Name Indice_PROBLAM_Estudiante2: problam!$B$18
Name Indice_PROBLAM_Estudiante3: problam!$B$19
Name Indice_PROBLAM_Estudiante4: problam!$B$20
Name Indice_PROBLAM_Estudiante5: problam!$B$21
Name Indice_PROBLAM_Estudiantes: Tabla_PROBLAM_Estudiantes[Estudiantes]
Name Indice_PROBLAM_NumEstudiantes: problam!$D$17
Name Indice_PROBLAM_Paquetes: Tabla_PROBLAM_Paquetes[Paquetes]
Name xx_Indice_PROBLAM_Historias_Conceptual: Tabla_PROBLAM_Artefactos1[Ciclo de vida]
Name xx_Indice_PROBLAM_Historias_DDL: Tabla_PROBLAM_Artefactos3[Diseño físico]
Name xx_Indice_PROBLAM_Historias_DML: Tabla_PROBLAM_Artefactos5[Gestión de transacciones]
Name xx_Indice_PROBLAM_Historias_Equipo: Tabla_PROBLAM_Artefactos4[Equipo]
Name xx_Indice_PROBLAM_Historias_Logico: Tabla_PROBLAM_Artefactos2[Ingeniería de datos]

Sheet plan
C2: ACTIVIDADES | G2: PLANIFICACIÓN | O2: IDEAL | R2: REALIDAD
B3: ID | C3: Actividad | D3: Paquete de trabajo | E3: Artefacto | F3: Especificación | G3: Responsable | H3: LPs individuales | I3: Learning Points | J3: Fecha de inicio Plan | K3: Fecha de fin Plan | L3: SemanaP | M3: Fecha límite | N3: Estado | O3: Fecha de inicio Ideal | P3: Fecha de fin Ideal | Q3: SemanaI | R3: Fecha de inicio Real | S3: Fecha de fin Real | T3: SemanaR | U3: Horas de trabajo | W3: MIEMBROS DEL EQUIPO
B4: 4 | C4: Comprensión del pliego técnico | D4: Equipo | E4: Gestión del proyecto | H4: 4 | I4: =Tabla_Plan_Actividad[[#This Row],[LPs individuales]]*Indice_PROBLAM_NumEstudiantes -> 20 | J4: 46097 | K4: 46100 | L4: =IF(K4<>"",1+INT((Tabla_Plan_Actividad[[#This Row],[Fecha de fin Plan]]-Indice_Plan_FechaInicio)/7),) -> 1 | M4: 46136 | N4: Sin iniciar | O4: 46097 | P4: 46100 | Q4: =IF(P4<>"",1+INT((Tabla_Plan_Actividad[[#This Row],[Fecha de fin Ideal]]-Indice_Plan_FechaInicio)/7),) -> 1 | R4: {=IF(plan!$N4<>Indice_PROBLAM_Aux_Estado_SinIniciar,INDEX(cronograma!$F$4:$AN$4,1,_xlfn.XMATCH(TRUE,cronograma!$F6:$AN6<>0,0)),Indice_Aux_SinFecha)} -> × | S4: {=IF(plan!$N4=Indice_PROBLAM_Aux_Estado_Finalizada,INDEX(cronograma!$F$4:$AL$4,1,_xlfn.XMATCH(TRUE,cronograma!$F6:$AL6<>0,0,-1)),Indice_Aux_SinFecha)} -> × | T4: {=IF(S4<>Indice_Aux_SinFecha,1+INT((Tabla_Plan_Actividad[[#This Row],[Fecha de fin Real]]-Indice_Plan_FechaInicio)/7),)} -> 0 | U4: =SUMIFS(Tabla_Registro_Tareas_Agregada[Minutos],Tabla_Registro_Tareas_Agregada[Actividad],plan!$C4)/60 -> 0 | W4: #1 | X4: Nombre#1 Apellido#11 Apellido#12
B5: 5 | C5: Reunión de inicio | D5: Equipo | E5: Gestión del proyecto | H5: 3 | I5: =Tabla_Plan_Actividad[[#This Row],[LPs individuales]]*Indice_PROBLAM_NumEstudiantes -> 15 | J5: 46100 | K5: 46101 | L5: =IF(K5<>"",1+INT((Tabla_Plan_Actividad[[#This Row],[Fecha de fin Plan]]-Indice_Plan_FechaInicio)/7),) -> 1 | M5: 46103 | N5: Sin iniciar | O5: 46100 | P5: 46101 | Q5: =IF(P5<>"",1+INT((Tabla_Plan_Actividad[[#This Row],[Fecha de fin Ideal]]-Indice_Plan_FechaInicio)/7),) -> 1 | R5: {=IF(plan!$N5<>Indice_PROBLAM_Aux_Estado_SinIniciar,INDEX(cronograma!$F$4:$AN$4,1,_xlfn.XMATCH(TRUE,cronograma!$F7:$AN7<>0,0)),Indice_Aux_SinFecha)} -> × | S5: {=IF(plan!$N5=Indice_PROBLAM_Aux_Estado_Finalizada,INDEX(cronograma!$F$4:$AL$4,1,_xlfn.XMATCH(TRUE,cronograma!$F7:$AL7<>0,0,-1)),Indice_Aux_SinFecha)} -> × | T5: {=IF(S5<>Indice_Aux_SinFecha,1+INT((Tabla_Plan_Actividad[[#This Row],[Fecha de fin Real]]-Indice_Plan_FechaInicio)/7),)} -> 0 | U5: =SUMIFS(Tabla_Registro_Tareas_Agregada[Minutos],Tabla_Registro_Tareas_Agregada[Actividad],plan!$C5)/60 -> 0 | W5: #2 | X5: Nombre#2 Apellido#21 Apellido#22
B6: 6 | C6: Gestión de cambios Diccionario | D6: Ciclo de vida | E6: Diccionario | H6: 1 | I6: =Tabla_Plan_Actividad[[#This Row],[LPs individuales]]*Indice_PROBLAM_NumEstudiantes -> 5 | J6: 46101 | K6: 46104 | L6: =IF(K6<>"",1+INT((Tabla_Plan_Actividad[[#This Row],[Fecha de fin Plan]]-Indice_Plan_FechaInicio)/7),) -> 2 | M6: 46136 | N6: Sin iniciar | O6: 46101 | P6: 46104 | Q6: =IF(P6<>"",1+INT((Tabla_Plan_Actividad[[#This Row],[Fecha de fin Ideal]]-Indice_Plan_FechaInicio)/7),) -> 2 | R6: {=IF(plan!$N6<>Indice_PROBLAM_Aux_Estado_SinIniciar,INDEX(cronograma!$F$4:$AN$4,1,_xlfn.XMATCH(TRUE,cronograma!$F8:$AN8<>0,0)),Indice_Aux_SinFecha)} -> × | S6: {=IF(plan!$N6=Indice_PROBLAM_Aux_Estado_Finalizada,INDEX(cronograma!$F$4:$AL$4,1,_xlfn.XMATCH(TRUE,cronograma!$F8:$AL8<>0,0,-1)),Indice_Aux_SinFecha)} -> × | T6: {=IF(S6<>Indice_Aux_SinFecha,1+INT((Tabla_Plan_Actividad[[#This Row],[Fecha de fin Real]]-Indice_Plan_FechaInicio)/7),)} -> 0 | U6: =SUMIFS(Tabla_Registro_Tareas_Agregada[Minutos],Tabla_Registro_Tareas_Agregada[Actividad],plan!$C6)/60 -> 0 | W6: #3 | X6: Nombre#3 Apellido#31 Apellido#32
B7: 7 | C7: Gestión de cambios Integridad | D7: Ciclo de vida | E7: Integridad avanzada | H7: 2 | I7: =Tabla_Plan_Actividad[[#This Row],[LPs individuales]]*Indice_PROBLAM_NumEstudiantes -> 10 | J7: 46104 | K7: 46105 | L7: =IF(K7<>"",1+INT((Tabla_Plan_Actividad[[#This Row],[Fecha de fin Plan]]-Indice_Plan_FechaInicio)/7),) -> 2 | M7: 46136 | N7: Sin iniciar | O7: 46104 | P7: 46105 | Q7: =IF(P7<>"",1+INT((Tabla_Plan_Actividad[[#This Row],[Fecha de fin Ideal]]-Indice_Plan_FechaInicio)/7),) -> 2 | R7: {=IF(plan!$N7<>Indice_PROBLAM_Aux_Estado_SinIniciar,INDEX(cronograma!$F$4:$AN$4,1,_xlfn.XMATCH(TRUE,cronograma!$F9:$AN9<>0,0)),Indice_Aux_SinFecha)} -> × | S7: {=IF(plan!$N7=Indice_PROBLAM_Aux_Estado_Finalizada,INDEX(cronograma!$F$4:$AL$4,1,_xlfn.XMATCH(TRUE,cronograma!$F9:$AL9<>0,0,-1)),Indice_Aux_SinFecha)} -> × | T7: {=IF(S7<>Indice_Aux_SinFecha,1+INT((Tabla_Plan_Actividad[[#This Row],[Fecha de fin Real]]-Indice_Plan_FechaInicio)/7),)} -> 0 | U7: =SUMIFS(Tabla_Registro_Tareas_Agregada[Minutos],Tabla_Registro_Tareas_Agregada[Actividad],plan!$C7)/60 -> 0 | W7: #4 | X7: Nombre#4 Apellido#41 Apellido#42
B8: 8 | C8: Gestión de cambios Procesos | D8: Ciclo de vida | E8: Procesos programados | H8: 2 | I8: =Tabla_Plan_Actividad[[#This Row],[LPs individuales]]*Indice_PROBLAM_NumEstudiantes -> 10 | J8: 46104 | K8: 46105 | L8: =IF(K8<>"",1+INT((Tabla_Plan_Actividad[[#This Row],[Fecha de fin Plan]]-Indice_Plan_FechaInicio)/7),) -> 2 | M8: 46136 | N8: Sin iniciar | O8: 46104 | P8: 46105 | Q8: =IF(P8<>"",1+INT((Tabla_Plan_Actividad[[#This Row],[Fecha de fin Ideal]]-Indice_Plan_FechaInicio)/7),) -> 2 | R8: {=IF(plan!$N8<>Indice_PROBLAM_Aux_Estado_SinIniciar,INDEX(cronograma!$F$4:$AN$4,1,_xlfn.XMATCH(TRUE,cronograma!$F10:$AN10<>0,0)),Indice_Aux_SinFecha)} -> × | S8: {=IF(plan!$N8=Indice_PROBLAM_Aux_Estado_Finalizada,INDEX(cronograma!$F$4:$AL$4,1,_xlfn.XMATCH(TRUE,cronograma!$F10:$AL10<>0,0,-1)),Indice_Aux_SinFecha)} -> × | T8: {=IF(S8<>Indice_Aux_SinFecha,1+INT((Tabla_Plan_Actividad[[#This Row],[Fecha de fin Real]]-Indice_Plan_FechaInicio)/7),)} -> 0 | U8: =SUMIFS(Tabla_Registro_Tareas_Agregada[Minutos],Tabla_Registro_Tareas_Agregada[Actividad],plan!$C8)/60 -> 0 | W8: #5 | X8: Nombre#5 Apellido#51 Apellido#52
B9: 9 | C9: Gestión de cambios ETL | D9: Ingeniería de datos | E9: ETL | H9: 7 | I9: =Tabla_Plan_Actividad[[#This Row],[LPs individuales]]*Indice_PROBLAM_NumEstudiantes -> 35 | J9: 46105 | K9: 46107 | L9: =IF(K9<>"",1+INT((Tabla_Plan_Actividad[[#This Row],[Fecha de fin Plan]]-Indice_Plan_FechaInicio)/7),) -> 2 | M9: 46136 | N9: Sin iniciar | O9: 46105 | P9: 46107 | Q9: =IF(P9<>"",1+INT((Tabla_Plan_Actividad[[#This Row],[Fecha de fin Ideal]]-Indice_Plan_FechaInicio)/7),) -> 2 | R9: {=IF(plan!$N9<>Indice_PROBLAM_Aux_Estado_SinIniciar,INDEX(cronograma!$F$4:$AN$4,1,_xlfn.XMATCH(TRUE,cronograma!$F11:$AN11<>0,0)),Indice_Aux_SinFecha)} -> × | S9: {=IF(plan!$N9=Indice_PROBLAM_Aux_Estado_Finalizada,INDEX(cronograma!$F$4:$AL$4,1,_xlfn.XMATCH(TRUE,cronograma!$F11:$AL11<>0,0,-1)),Indice_Aux_SinFecha)} -> × | T9: {=IF(S9<>Indice_Aux_SinFecha,1+INT((Tabla_Plan_Actividad[[#This Row],[Fecha de fin Real]]-Indice_Plan_FechaInicio)/7),)} -> 0 | U9: =SUMIFS(Tabla_Registro_Tareas_Agregada[Minutos],Tabla_Registro_Tareas_Agregada[Actividad],plan!$C9)/60 -> 0
B10: 10 | C10: Gestión de cambios Datos sintéticos | D10: Ingeniería de datos | E10: Datos sintéticos | H10: 7 | I10: =Tabla_Plan_Actividad[[#This Row],[LPs individuales]]*Indice_PROBLAM_NumEstudiantes -> 35 | J10: 46105 | K10: 46107 | L10: =IF(K10<>"",1+INT((Tabla_Plan_Actividad[[#This Row],[Fecha de fin Plan]]-Indice_Plan_FechaInicio)/7),) -> 2 | M10: 46136 | N10: Sin iniciar | O10: 46105 | P10: 46107 | Q10: =IF(P10<>"",1+INT((Tabla_Plan_Actividad[[#This Row],[Fecha de fin Ideal]]-Indice_Plan_FechaInicio)/7),) -> 2 | R10: {=IF(plan!$N10<>Indice_PROBLAM_Aux_Estado_SinIniciar,INDEX(cronograma!$F$4:$AN$4,1,_xlfn.XMATCH(TRUE,cronograma!$F12:$AN12<>0,0)),Indice_Aux_SinFecha)} -> × | S10: {=IF(plan!$N10=Indice_PROBLAM_Aux_Estado_Finalizada,INDEX(cronograma!$F$4:$AL$4,1,_xlfn.XMATCH(TRUE,cronograma!$F12:$AL12<>0,0,-1)),Indice_Aux_SinFecha)} -> × | T10: {=IF(S10<>Indice_Aux_SinFecha,1+INT((Tabla_Plan_Actividad[[#This Row],[Fecha de fin Real]]-Indice_Plan_FechaInicio)/7),)} -> 0 | U10: =SUMIFS(Tabla_Registro_Tareas_Agregada[Minutos],Tabla_Registro_Tareas_Agregada[Actividad],plan!$C10)/60 -> 0
B11: 11 | C11: Reunión de sincronización #1 | D11: Equipo | E11: Gestión del proyecto | H11: 1 | I11: =Tabla_Plan_Actividad[[#This Row],[LPs individuales]]*Indice_PROBLAM_NumEstudiantes -> 5 | J11: 46108 | K11: 46108 | L11: =IF(K11<>"",1+INT((Tabla_Plan_Actividad[[#This Row],[Fecha de fin Plan]]-Indice_Plan_FechaInicio)/7),) -> 2 | M11: 46110 | N11: Sin iniciar | O11: 46108 | P11: 46108 | Q11: =IF(P11<>"",1+INT((Tabla_Plan_Actividad[[#This Row],[Fecha de fin Ideal]]-Indice_Plan_FechaInicio)/7),) -> 2 | R11: {=IF(plan!$N11<>Indice_PROBLAM_Aux_Estado_SinIniciar,INDEX(cronograma!$F$4:$AN$4,1,_xlfn.XMATCH(TRUE,cronograma!$F13:$AN13<>0,0)),Indice_Aux_SinFecha)} -> × | S11: {=IF(plan!$N11=Indice_PROBLAM_Aux_Estado_Finalizada,INDEX(cronograma!$F$4:$AL$4,1,_xlfn.XMATCH(TRUE,cronograma!$F13:$AL13<>0,0,-1)),Indice_Aux_SinFecha)} -> × | T11: {=IF(S11<>Indice_Aux_SinFecha,1+INT((Tabla_Plan_Actividad[[#This Row],[Fecha de fin Real]]-Indice_Plan_FechaInicio)/7),)} -> 0 | U11: =SUMIFS(Tabla_Registro_Tareas_Agregada[Minutos],Tabla_Registro_Tareas_Agregada[Actividad],plan!$C11)/60 -> 0
B12: 12 | C12: Evaluar baseline de almacenamiento | D12: Diseño físico | E12: Almacenamiento | H12: 12 | I12: =Tabla_Plan_Actividad[[#This Row],[LPs individuales]]*Indice_PROBLAM_NumEstudiantes -> 60 | J12: 46119 | K12: 46123 | L12: =IF(K12<>"",1+INT((Tabla_Plan_Actividad[[#This Row],[Fecha de fin Plan]]-Indice_Plan_FechaInicio)/7),) -> 4 | M12: 46136 | N12: Sin iniciar | O12: 46119 | P12: 46123 | Q12: =IF(P12<>"",1+INT((Tabla_Plan_Actividad[[#This Row],[Fecha de fin Ideal]]-Indice_Plan_FechaInicio)/7),) -> 4 | R12: {=IF(plan!$N12<>Indice_PROBLAM_Aux_Estado_SinIniciar,INDEX(cronograma!$F$4:$AN$4,1,_xlfn.XMATCH(TRUE,cronograma!$F14:$AN14<>0,0)),Indice_Aux_SinFecha)} -> × | S12: {=IF(plan!$N12=Indice_PROBLAM_Aux_Estado_Finalizada,INDEX(cronograma!$F$4:$AL$4,1,_xlfn.XMATCH(TRUE,cronograma!$F14:$AL14<>0,0,-1)),Indice_Aux_SinFecha)} -> × | T12: {=IF(S12<>Indice_Aux_SinFecha,1+INT((Tabla_Plan_Actividad[[#This Row],[Fecha de fin Real]]-Indice_Plan_FechaInicio)/7),)} -> 0 | U12: =SUMIFS(Tabla_Registro_Tareas_Agregada[Minutos],Tabla_Registro_Tareas_Agregada[Actividad],plan!$C12)/60 -> 0
B13: 13 | C13: ETLs Sprint #2 | D13: Ingeniería de datos | E13: ETL | H13: 4 | I13: =Tabla_Plan_Actividad[[#This Row],[LPs individuales]]*Indice_PROBLAM_NumEstudiantes -> 20 | J13: 46121 | K13: 46126 | L13: =IF(K13<>"",1+INT((Tabla_Plan_Actividad[[#This Row],[Fecha de fin Plan]]-Indice_Plan_FechaInicio)/7),) -> 5 | M13: 46136 | N13: Sin iniciar | O13: 46121 | P13: 46126 | Q13: =IF(P13<>"",1+INT((Tabla_Plan_Actividad[[#This Row],[Fecha de fin Ideal]]-Indice_Plan_FechaInicio)/7),) -> 5 | R13: {=IF(plan!$N13<>Indice_PROBLAM_Aux_Estado_SinIniciar,INDEX(cronograma!$F$4:$AN$4,1,_xlfn.XMATCH(TRUE,cronograma!$F15:$AN15<>0,0)),Indice_Aux_SinFecha)} -> × | S13: {=IF(plan!$N13=Indice_PROBLAM_Aux_Estado_Finalizada,INDEX(cronograma!$F$4:$AL$4,1,_xlfn.XMATCH(TRUE,cronograma!$F15:$AL15<>0,0,-1)),Indice_Aux_SinFecha)} -> × | T13: {=IF(S13<>Indice_Aux_SinFecha,1+INT((Tabla_Plan_Actividad[[#This Row],[Fecha de fin Real]]-Indice_Plan_FechaInicio)/7),)} -> 0 | U13: =SUMIFS(Tabla_Registro_Tareas_Agregada[Minutos],Tabla_Registro_Tareas_Agregada[Actividad],plan!$C13)/60 -> 0
B14: 14 | C14: Generar datos sintéticos Sprint #2 | D14: Equipo | E14: Gestión del proyecto | H14: 4 | I14: =Tabla_Plan_Actividad[[#This Row],[LPs individuales]]*Indice_PROBLAM_NumEstudiantes -> 20 | J14: 46121 | K14: 46126 | L14: =IF(K14<>"",1+INT((Tabla_Plan_Actividad[[#This Row],[Fecha de fin Plan]]-Indice_Plan_FechaInicio)/7),) -> 5 | M14: 46136 | N14: Sin iniciar | O14: 46121 | P14: 46126 | Q14: =IF(P14<>"",1+INT((Tabla_Plan_Actividad[[#This Row],[Fecha de fin Ideal]]-Indice_Plan_FechaInicio)/7),) -> 5 | R14: {=IF(plan!$N14<>Indice_PROBLAM_Aux_Estado_SinIniciar,INDEX(cronograma!$F$4:$AN$4,1,_xlfn.XMATCH(TRUE,cronograma!$F16:$AN16<>0,0)),Indice_Aux_SinFecha)} -> × | S14: {=IF(plan!$N14=Indice_PROBLAM_Aux_Estado_Finalizada,INDEX(cronograma!$F$4:$AL$4,1,_xlfn.XMATCH(TRUE,cronograma!$F16:$AL16<>0,0,-1)),Indice_Aux_SinFecha)} -> × | T14: {=IF(S14<>Indice_Aux_SinFecha,1+INT((Tabla_Plan_Actividad[[#This Row],[Fecha de fin Real]]-Indice_Plan_FechaInicio)/7),)} -> 0 | U14: =SUMIFS(Tabla_Registro_Tareas_Agregada[Minutos],Tabla_Registro_Tareas_Agregada[Actividad],plan!$C14)/60 -> 0
B15: 15 | C15: Reunión de sincronización #2 | D15: Equipo | E15: Gestión del proyecto | H15: 1 | I15: 5 | J15: 46122 | K15: 46122 | L15: 4 | M15: 46124 | N15: Sin iniciar | O15: 46127 | P15: 46127 | Q15: =IF(P15<>"",1+INT((Tabla_Plan_Actividad[[#This Row],[Fecha de fin Ideal]]-Indice_Plan_FechaInicio)/7),) -> 5 | R15: {=IF(plan!$N15<>Indice_PROBLAM_Aux_Estado_SinIniciar,INDEX(cronograma!$F$4:$AN$4,1,_xlfn.XMATCH(TRUE,cronograma!$F17:$AN17<>0,0)),Indice_Aux_SinFecha)} -> × | S15: {=IF(plan!$N15=Indice_PROBLAM_Aux_Estado_Finalizada,INDEX(cronograma!$F$4:$AL$4,1,_xlfn.XMATCH(TRUE,cronograma!$F17:$AL17<>0,0,-1)),Indice_Aux_SinFecha)} -> × | T15: {=IF(S15<>Indice_Aux_SinFecha,1+INT((Tabla_Plan_Actividad[[#This Row],[Fecha de fin Real]]-Indice_Plan_FechaInicio)/7),)} -> 0 | U15: =SUMIFS(Tabla_Registro_Tareas_Agregada[Minutos],Tabla_Registro_Tareas_Agregada[Actividad],plan!$C15)/60 -> 0
B16: 16 | C16: Actualizar diccionario | D16: Ciclo de vida | E16: Diccionario | H16: 1 | I16: =Tabla_Plan_Actividad[[#This Row],[LPs individuales]]*Indice_PROBLAM_NumEstudiantes -> 5 | J16: 46127 | K16: 46127 | L16: =IF(K16<>"",1+INT((Tabla_Plan_Actividad[[#This Row],[Fecha de fin Plan]]-Indice_Plan_FechaInicio)/7),) -> 5 | M16: 46136 | N16: Sin iniciar | O16: 46122 | P16: 46122 | Q16: =IF(P16<>"",1+INT((Tabla_Plan_Actividad[[#This Row],[Fecha de fin Ideal]]-Indice_Plan_FechaInicio)/7),) -> 4 | R16: {=IF(plan!$N16<>Indice_PROBLAM_Aux_Estado_SinIniciar,INDEX(cronograma!$F$4:$AN$4,1,_xlfn.XMATCH(TRUE,cronograma!$F18:$AN18<>0,0)),Indice_Aux_SinFecha)} -> × | S16: {=IF(plan!$N16=Indice_PROBLAM_Aux_Estado_Finalizada,INDEX(cronograma!$F$4:$AL$4,1,_xlfn.XMATCH(TRUE,cronograma!$F18:$AL18<>0,0,-1)),Indice_Aux_SinFecha)} -> × | T16: {=IF(S16<>Indice_Aux_SinFecha,1+INT((Tabla_Plan_Actividad[[#This Row],[Fecha de fin Real]]-Indice_Plan_FechaInicio)/7),)} -> 0 | U16: =SUMIFS(Tabla_Registro_Tareas_Agregada[Minutos],Tabla_Registro_Tareas_Agregada[Actividad],plan!$C16)/60 -> 0
B17: 17 | C17: Implementar funcionalidades | D17: Diseño físico | E17: Indexación | H17: 8 | I17: 40 | J17: 46127 | K17: 46129 | L17: 5 | M17: 46136 | N17: =IF(ISNUMBER(MATCH(plan!$C17, Tabla_Registro_Tareas1[Actividad], 0)),Indice_PROBLAM_Aux_Estado_Desarrollo,Indice_PROBLAM_Aux_Estado_SinIniciar) -> Sin iniciar | O17: 46127 | P17: 46129 | Q17: =IF(P17<>"",1+INT((Tabla_Plan_Actividad[[#This Row],[Fecha de fin Ideal]]-Indice_Plan_FechaInicio)/7),) -> 5 | R17: {=IF(plan!$N17<>Indice_PROBLAM_Aux_Estado_SinIniciar,INDEX(cronograma!$F$4:$AN$4,1,_xlfn.XMATCH(TRUE,cronograma!$F19:$AN19<>0,0)),Indice_Aux_SinFecha)} -> × | S17: {=IF(plan!$N17=Indice_PROBLAM_Aux_Estado_Finalizada,INDEX(cronograma!$F$4:$AL$4,1,_xlfn.XMATCH(TRUE,cronograma!$F19:$AL19<>0,0,-1)),Indice_Aux_SinFecha)} -> × | T17: {=IF(S17<>Indice_Aux_SinFecha,1+INT((Tabla_Plan_Actividad[[#This Row],[Fecha de fin Real]]-Indice_Plan_FechaInicio)/7),)} -> 0 | U17: =SUMIFS(Tabla_Registro_Tareas_Agregada[Minutos],Tabla_Registro_Tareas_Agregada[Actividad],plan!$C17)/60 -> 0
B18: 18 | C18: Evaluar indexación | D18: Diseño físico | E18: Indexación | H18: 12 | I18: 50 | J18: 46129 | K18: 46134 | L18: 6 | M18: 46136 | N18: =IF(ISNUMBER(MATCH(plan!$C18, Tabla_Registro_Tareas1[Actividad], 0)),Indice_PROBLAM_Aux_Estado_Desarrollo,Indice_PROBLAM_Aux_Estado_SinIniciar) -> Sin iniciar | O18: 46129 | P18: 46134 | Q18: =IF(P18<>"",1+INT((Tabla_Plan_Actividad[[#This Row],[Fecha de fin Ideal]]-Indice_Plan_FechaInicio)/7),) -> 6 | R18: {=IF(plan!$N18<>Indice_PROBLAM_Aux_Estado_SinIniciar,INDEX(cronograma!$F$4:$AN$4,1,_xlfn.XMATCH(TRUE,cronograma!$F20:$AN20<>0,0)),Indice_Aux_SinFecha)} -> × | S18: {=IF(plan!$N18=Indice_PROBLAM_Aux_Estado_Finalizada,INDEX(cronograma!$F$4:$AL$4,1,_xlfn.XMATCH(TRUE,cronograma!$F20:$AL20<>0,0,-1)),Indice_Aux_SinFecha)} -> × | T18: {=IF(S18<>Indice_Aux_SinFecha,1+INT((Tabla_Plan_Actividad[[#This Row],[Fecha de fin Real]]-Indice_Plan_FechaInicio)/7),)} -> 0 | U18: =SUMIFS(Tabla_Registro_Tareas_Agregada[Minutos],Tabla_Registro_Tareas_Agregada[Actividad],plan!$C18)/60 -> 0
B19: 19 | C19: Reunión de sincronización #3 | D19: Equipo | E19: Gestión del proyecto | H19: 1 | I19: 5 | J19: 46129 | K19: 46129 | L19: 5 | M19: 46131 | N19: =IF(ISNUMBER(MATCH(plan!$C19, Tabla_Registro_Tareas1[Actividad], 0)),Indice_PROBLAM_Aux_Estado_Desarrollo,Indice_PROBLAM_Aux_Estado_SinIniciar) -> Sin iniciar | O19: 46129 | P19: 46129 | Q19: =IF(P19<>"",1+INT((Tabla_Plan_Actividad[[#This Row],[Fecha de fin Ideal]]-Indice_Plan_FechaInicio)/7),) -> 5 | R19: {=IF(plan!$N19<>Indice_PROBLAM_Aux_Estado_SinIniciar,INDEX(cronograma!$F$4:$AN$4,1,_xlfn.XMATCH(TRUE,cronograma!$F21:$AN21<>0,0)),Indice_Aux_SinFecha)} -> × | S19: {=IF(plan!$N19=Indice_PROBLAM_Aux_Estado_Finalizada,INDEX(cronograma!$F$4:$AL$4,1,_xlfn.XMATCH(TRUE,cronograma!$F21:$AL21<>0,0,-1)),Indice_Aux_SinFecha)} -> × | T19: {=IF(S19<>Indice_Aux_SinFecha,1+INT((Tabla_Plan_Actividad[[#This Row],[Fecha de fin Real]]-Indice_Plan_FechaInicio)/7),)} -> 0 | U19: =SUMIFS(Tabla_Registro_Tareas_Agregada[Minutos],Tabla_Registro_Tareas_Agregada[Actividad],plan!$C19)/60 -> 0
B20: 20 | C20: Retrospectiva | D20: Equipo | E20: Gestión del proyecto | H20: 2 | I20: =Tabla_Plan_Actividad[[#This Row],[LPs individuales]]*Indice_PROBLAM_NumEstudiantes -> 10 | J20: 46136 | K20: 46136 | L20: =IF(K20<>"",1+INT((Tabla_Plan_Actividad[[#This Row],[Fecha de fin Plan]]-Indice_Plan_FechaInicio)/7),) -> 6 | M20: 46136 | N20: =IF(ISNUMBER(MATCH(plan!$C20, Tabla_Registro_Tareas1[Actividad], 0)),Indice_PROBLAM_Aux_Estado_Desarrollo,Indice_PROBLAM_Aux_Estado_SinIniciar) -> Sin iniciar | O20: 46136 | P20: 46136 | Q20: =IF(P20<>"",1+INT((Tabla_Plan_Actividad[[#This Row],[Fecha de fin Ideal]]-Indice_Plan_FechaInicio)/7),) -> 6 | R20: {=IF(plan!$N20<>Indice_PROBLAM_Aux_Estado_SinIniciar,INDEX(cronograma!$F$4:$AN$4,1,_xlfn.XMATCH(TRUE,cronograma!$F22:$AN22<>0,0)),Indice_Aux_SinFecha)} -> × | S20: {=IF(plan!$N20=Indice_PROBLAM_Aux_Estado_Finalizada,INDEX(cronograma!$F$4:$AL$4,1,_xlfn.XMATCH(TRUE,cronograma!$F22:$AL22<>0,0,-1)),Indice_Aux_SinFecha)} -> × | T20: {=IF(S20<>Indice_Aux_SinFecha,1+INT((Tabla_Plan_Actividad[[#This Row],[Fecha de fin Real]]-Indice_Plan_FechaInicio)/7),)} -> 0 | U20: =SUMIFS(Tabla_Registro_Tareas_Agregada[Minutos],Tabla_Registro_Tareas_Agregada[Actividad],plan!$C20)/60 -> 0
B21: 21 | C21: Evaluación de la actividad del equipo | D21: Equipo | E21: Evaluación de la actividad | H21: 1 | I21: =Tabla_Plan_Actividad[[#This Row],[LPs individuales]]*Indice_PROBLAM_NumEstudiantes -> 5 | J21: 46136 | K21: 46136 | L21: =IF(K21<>"",1+INT((Tabla_Plan_Actividad[[#This Row],[Fecha de fin Plan]]-Indice_Plan_FechaInicio)/7),) -> 6 | M21: 46136 | N21: =IF(ISNUMBER(MATCH(plan!$C21, Tabla_Registro_Tareas1[Actividad], 0)),Indice_PROBLAM_Aux_Estado_Desarrollo,Indice_PROBLAM_Aux_Estado_SinIniciar) -> Sin iniciar | O21: 46136 | P21: 46136 | Q21: =IF(P21<>"",1+INT((Tabla_Plan_Actividad[[#This Row],[Fecha de fin Ideal]]-Indice_Plan_FechaInicio)/7),) -> 6 | R21: {=IF(plan!$N21<>Indice_PROBLAM_Aux_Estado_SinIniciar,INDEX(cronograma!$F$4:$AN$4,1,_xlfn.XMATCH(TRUE,cronograma!$F23:$AN23<>0,0)),Indice_Aux_SinFecha)} -> × | S21: {=IF(plan!$N21=Indice_PROBLAM_Aux_Estado_Finalizada,INDEX(cronograma!$F$4:$AL$4,1,_xlfn.XMATCH(TRUE,cronograma!$F23:$AL23<>0,0,-1)),Indice_Aux_SinFecha)} -> × | T21: {=IF(S21<>Indice_Aux_SinFecha,1+INT((Tabla_Plan_Actividad[[#This Row],[Fecha de fin Real]]-Indice_Plan_FechaInicio)/7),)} -> 0 | U21: =SUMIFS(Tabla_Registro_Tareas_Agregada[Minutos],Tabla_Registro_Tareas_Agregada[Actividad],plan!$C21)/60 -> 0
B22: 22 | C22: Entrega del incremento | D22: Equipo | E22: Incremento | H22: 1 | I22: =Tabla_Plan_Actividad[[#This Row],[LPs individuales]]*Indice_PROBLAM_NumEstudiantes -> 5 | J22: 46136 | K22: 46136 | L22: =IF(K22<>"",1+INT((Tabla_Plan_Actividad[[#This Row],[Fecha de fin Plan]]-Indice_Plan_FechaInicio)/7),) -> 6 | M22: 46136 | N22: =IF(ISNUMBER(MATCH(plan!$C22, Tabla_Registro_Tareas1[Actividad], 0)),Indice_PROBLAM_Aux_Estado_Desarrollo,Indice_PROBLAM_Aux_Estado_SinIniciar) -> Sin iniciar | O22: 46136 | P22: 46136 | Q22: =IF(P22<>"",1+INT((Tabla_Plan_Actividad[[#This Row],[Fecha de fin Ideal]]-Indice_Plan_FechaInicio)/7),) -> 6 | R22: {=IF(plan!$N22<>Indice_PROBLAM_Aux_Estado_SinIniciar,INDEX(cronograma!$F$4:$AN$4,1,_xlfn.XMATCH(TRUE,cronograma!$F24:$AN24<>0,0)),Indice_Aux_SinFecha)} -> × | S22: {=IF(plan!$N22=Indice_PROBLAM_Aux_Estado_Finalizada,INDEX(cronograma!$F$4:$AL$4,1,_xlfn.XMATCH(TRUE,cronograma!$F24:$AL24<>0,0,-1)),Indice_Aux_SinFecha)} -> × | T22: {=IF(S22<>Indice_Aux_SinFecha,1+INT((Tabla_Plan_Actividad[[#This Row],[Fecha de fin Real]]-Indice_Plan_FechaInicio)/7),)} -> 0 | U22: =SUMIFS(Tabla_Registro_Tareas_Agregada[Minutos],Tabla_Registro_Tareas_Agregada[Actividad],plan!$C22)/60 -> 0
B23: 23 | C23: Reuniones no planificadas | D23: Equipo | E23: Gestión del proyecto | I23: =Tabla_Plan_Actividad[[#This Row],[LPs individuales]]*Indice_PROBLAM_NumEstudiantes -> 0 | L23: =IF(K23<>"",1+INT((Tabla_Plan_Actividad[[#This Row],[Fecha de fin Plan]]-Indice_Plan_FechaInicio)/7),) -> 0 | N23: =IF(ISNUMBER(MATCH(plan!$C23, Tabla_Registro_Tareas1[Actividad], 0)),Indice_PROBLAM_Aux_Estado_Desarrollo,Indice_PROBLAM_Aux_Estado_SinIniciar) -> Sin iniciar | Q23: =IF(P23<>"",1+INT((Tabla_Plan_Actividad[[#This Row],[Fecha de fin Ideal]]-Indice_Plan_FechaInicio)/7),) -> 0 | R23: {=IF(plan!$N23<>Indice_PROBLAM_Aux_Estado_SinIniciar,INDEX(cronograma!$F$4:$AN$4,1,_xlfn.XMATCH(TRUE,cronograma!$F25:$AN25<>0,0)),Indice_Aux_SinFecha)} -> × | S23: {=IF(plan!$N23=Indice_PROBLAM_Aux_Estado_Finalizada,INDEX(cronograma!$F$4:$AL$4,1,_xlfn.XMATCH(TRUE,cronograma!$F25:$AL25<>0,0,-1)),Indice_Aux_SinFecha)} -> × | T23: {=IF(S23<>Indice_Aux_SinFecha,1+INT((Tabla_Plan_Actividad[[#This Row],[Fecha de fin Real]]-Indice_Plan_FechaInicio)/7),)} -> 0 | U23: =SUMIFS(Tabla_Registro_Tareas_Agregada[Minutos],Tabla_Registro_Tareas_Agregada[Actividad],plan!$C23)/60 -> 0
B24: 24 | I24: =Tabla_Plan_Actividad[[#This Row],[LPs individuales]]*Indice_PROBLAM_NumEstudiantes -> 0 | L24: =IF(K24<>"",1+INT((Tabla_Plan_Actividad[[#This Row],[Fecha de fin Plan]]-Indice_Plan_FechaInicio)/7),) -> 0 | N24: =IF(ISNUMBER(MATCH(plan!$C24, Tabla_Registro_Tareas1[Actividad], 0)),Indice_PROBLAM_Aux_Estado_Desarrollo,Indice_PROBLAM_Aux_Estado_SinIniciar) -> Sin iniciar | Q24: =IF(P24<>"",1+INT((Tabla_Plan_Actividad[[#This Row],[Fecha de fin Ideal]]-Indice_Plan_FechaInicio)/7),) -> 0 | R24: {=IF(plan!$N24<>Indice_PROBLAM_Aux_Estado_SinIniciar,INDEX(cronograma!$F$4:$AN$4,1,_xlfn.XMATCH(TRUE,cronograma!$F26:$AN26<>0,0)),Indice_Aux_SinFecha)} -> × | S24: {=IF(plan!$N24=Indice_PROBLAM_Aux_Estado_Finalizada,INDEX(cronograma!$F$4:$AL$4,1,_xlfn.XMATCH(TRUE,cronograma!$F26:$AL26<>0,0,-1)),Indice_Aux_SinFecha)} -> × | T24: {=IF(S24<>Indice_Aux_SinFecha,1+INT((Tabla_Plan_Actividad[[#This Row],[Fecha de fin Real]]-Indice_Plan_FechaInicio)/7),)} -> 0 | U24: =SUMIFS(Tabla_Registro_Tareas_Agregada[Minutos],Tabla_Registro_Tareas_Agregada[Actividad],plan!$C24)/60 -> 0
B25: 25 | I25: =Tabla_Plan_Actividad[[#This Row],[LPs individuales]]*Indice_PROBLAM_NumEstudiantes -> 0 | L25: =IF(K25<>"",1+INT((Tabla_Plan_Actividad[[#This Row],[Fecha de fin Plan]]-Indice_Plan_FechaInicio)/7),) -> 0 | N25: =IF(ISNUMBER(MATCH(plan!$C25, Tabla_Registro_Tareas1[Actividad], 0)),Indice_PROBLAM_Aux_Estado_Desarrollo,Indice_PROBLAM_Aux_Estado_SinIniciar) -> Sin iniciar | Q25: =IF(P25<>"",1+INT((Tabla_Plan_Actividad[[#This Row],[Fecha de fin Ideal]]-Indice_Plan_FechaInicio)/7),) -> 0 | R25: {=IF(plan!$N25<>Indice_PROBLAM_Aux_Estado_SinIniciar,INDEX(cronograma!$F$4:$AN$4,1,_xlfn.XMATCH(TRUE,cronograma!$F27:$AN27<>0,0)),Indice_Aux_SinFecha)} -> × | S25: {=IF(plan!$N25=Indice_PROBLAM_Aux_Estado_Finalizada,INDEX(cronograma!$F$4:$AL$4,1,_xlfn.XMATCH(TRUE,cronograma!$F27:$AL27<>0,0,-1)),Indice_Aux_SinFecha)} -> × | T25: {=IF(S25<>Indice_Aux_SinFecha,1+INT((Tabla_Plan_Actividad[[#This Row],[Fecha de fin Real]]-Indice_Plan_FechaInicio)/7),)} -> 0 | U25: =SUMIFS(Tabla_Registro_Tareas_Agregada[Minutos],Tabla_Registro_Tareas_Agregada[Actividad],plan!$C25)/60 -> 0
B26: 26 | I26: =Tabla_Plan_Actividad[[#This Row],[LPs individuales]]*Indice_PROBLAM_NumEstudiantes -> 0 | L26: =IF(K26<>"",1+INT((Tabla_Plan_Actividad[[#This Row],[Fecha de fin Plan]]-Indice_Plan_FechaInicio)/7),) -> 0 | N26: =IF(ISNUMBER(MATCH(plan!$C26, Tabla_Registro_Tareas1[Actividad], 0)),Indice_PROBLAM_Aux_Estado_Desarrollo,Indice_PROBLAM_Aux_Estado_SinIniciar) -> Sin iniciar | Q26: =IF(P26<>"",1+INT((Tabla_Plan_Actividad[[#This Row],[Fecha de fin Ideal]]-Indice_Plan_FechaInicio)/7),) -> 0 | R26: {=IF(plan!$N26<>Indice_PROBLAM_Aux_Estado_SinIniciar,INDEX(cronograma!$F$4:$AN$4,1,_xlfn.XMATCH(TRUE,cronograma!$F28:$AN28<>0,0)),Indice_Aux_SinFecha)} -> × | S26: {=IF(plan!$N26=Indice_PROBLAM_Aux_Estado_Finalizada,INDEX(cronograma!$F$4:$AL$4,1,_xlfn.XMATCH(TRUE,cronograma!$F28:$AL28<>0,0,-1)),Indice_Aux_SinFecha)} -> × | T26: {=IF(S26<>Indice_Aux_SinFecha,1+INT((Tabla_Plan_Actividad[[#This Row],[Fecha de fin Real]]-Indice_Plan_FechaInicio)/7),)} -> 0 | U26: =SUMIFS(Tabla_Registro_Tareas_Agregada[Minutos],Tabla_Registro_Tareas_Agregada[Actividad],plan!$C26)/60 -> 0
B27: 27 | I27: =Tabla_Plan_Actividad[[#This Row],[LPs individuales]]*Indice_PROBLAM_NumEstudiantes -> 0 | L27: =IF(K27<>"",1+INT((Tabla_Plan_Actividad[[#This Row],[Fecha de fin Plan]]-Indice_Plan_FechaInicio)/7),) -> 0 | N27: =IF(ISNUMBER(MATCH(plan!$C27, Tabla_Registro_Tareas1[Actividad], 0)),Indice_PROBLAM_Aux_Estado_Desarrollo,Indice_PROBLAM_Aux_Estado_SinIniciar) -> Sin iniciar | Q27: =IF(P27<>"",1+INT((Tabla_Plan_Actividad[[#This Row],[Fecha de fin Ideal]]-Indice_Plan_FechaInicio)/7),) -> 0 | R27: {=IF(plan!$N27<>Indice_PROBLAM_Aux_Estado_SinIniciar,INDEX(cronograma!$F$4:$AN$4,1,_xlfn.XMATCH(TRUE,cronograma!$F29:$AN29<>0,0)),Indice_Aux_SinFecha)} -> × | S27: {=IF(plan!$N27=Indice_PROBLAM_Aux_Estado_Finalizada,INDEX(cronograma!$F$4:$AL$4,1,_xlfn.XMATCH(TRUE,cronograma!$F29:$AL29<>0,0,-1)),Indice_Aux_SinFecha)} -> × | T27: {=IF(S27<>Indice_Aux_SinFecha,1+INT((Tabla_Plan_Actividad[[#This Row],[Fecha de fin Real]]-Indice_Plan_FechaInicio)/7),)} -> 0 | U27: =SUMIFS(Tabla_Registro_Tareas_Agregada[Minutos],Tabla_Registro_Tareas_Agregada[Actividad],plan!$C27)/60 -> 0
B28: 28 | I28: =Tabla_Plan_Actividad[[#This Row],[LPs individuales]]*Indice_PROBLAM_NumEstudiantes -> 0 | L28: =IF(K28<>"",1+INT((Tabla_Plan_Actividad[[#This Row],[Fecha de fin Plan]]-Indice_Plan_FechaInicio)/7),) -> 0 | N28: =IF(ISNUMBER(MATCH(plan!$C28, Tabla_Registro_Tareas1[Actividad], 0)),Indice_PROBLAM_Aux_Estado_Desarrollo,Indice_PROBLAM_Aux_Estado_SinIniciar) -> Sin iniciar | Q28: =IF(P28<>"",1+INT((Tabla_Plan_Actividad[[#This Row],[Fecha de fin Ideal]]-Indice_Plan_FechaInicio)/7),) -> 0 | R28: {=IF(plan!$N28<>Indice_PROBLAM_Aux_Estado_SinIniciar,INDEX(cronograma!$F$4:$AN$4,1,_xlfn.XMATCH(TRUE,cronograma!$F30:$AN30<>0,0)),Indice_Aux_SinFecha)} -> × | S28: {=IF(plan!$N28=Indice_PROBLAM_Aux_Estado_Finalizada,INDEX(cronograma!$F$4:$AL$4,1,_xlfn.XMATCH(TRUE,cronograma!$F30:$AL30<>0,0,-1)),Indice_Aux_SinFecha)} -> × | T28: {=IF(S28<>Indice_Aux_SinFecha,1+INT((Tabla_Plan_Actividad[[#This Row],[Fecha de fin Real]]-Indice_Plan_FechaInicio)/7),)} -> 0 | U28: =SUMIFS(Tabla_Registro_Tareas_Agregada[Minutos],Tabla_Registro_Tareas_Agregada[Actividad],plan!$C28)/60 -> 0
B29: 29 | I29: =Tabla_Plan_Actividad[[#This Row],[LPs individuales]]*Indice_PROBLAM_NumEstudiantes -> 0 | L29: =IF(K29<>"",1+INT((Tabla_Plan_Actividad[[#This Row],[Fecha de fin Plan]]-Indice_Plan_FechaInicio)/7),) -> 0 | N29: =IF(ISNUMBER(MATCH(plan!$C29, Tabla_Registro_Tareas1[Actividad], 0)),Indice_PROBLAM_Aux_Estado_Desarrollo,Indice_PROBLAM_Aux_Estado_SinIniciar) -> Sin iniciar | Q29: =IF(P29<>"",1+INT((Tabla_Plan_Actividad[[#This Row],[Fecha de fin Ideal]]-Indice_Plan_FechaInicio)/7),) -> 0 | R29: {=IF(plan!$N29<>Indice_PROBLAM_Aux_Estado_SinIniciar,INDEX(cronograma!$F$4:$AN$4,1,_xlfn.XMATCH(TRUE,cronograma!$F31:$AN31<>0,0)),Indice_Aux_SinFecha)} -> × | S29: {=IF(plan!$N29=Indice_PROBLAM_Aux_Estado_Finalizada,INDEX(cronograma!$F$4:$AL$4,1,_xlfn.XMATCH(TRUE,cronograma!$F31:$AL31<>0,0,-1)),Indice_Aux_SinFecha)} -> × | T29: {=IF(S29<>Indice_Aux_SinFecha,1+INT((Tabla_Plan_Actividad[[#This Row],[Fecha de fin Real]]-Indice_Plan_FechaInicio)/7),)} -> 0 | U29: =SUMIFS(Tabla_Registro_Tareas_Agregada[Minutos],Tabla_Registro_Tareas_Agregada[Actividad],plan!$C29)/60 -> 0
B30: 30 | I30: =Tabla_Plan_Actividad[[#This Row],[LPs individuales]]*Indice_PROBLAM_NumEstudiantes -> 0 | L30: =IF(K30<>"",1+INT((Tabla_Plan_Actividad[[#This Row],[Fecha de fin Plan]]-Indice_Plan_FechaInicio)/7),) -> 0 | N30: =IF(ISNUMBER(MATCH(plan!$C30, Tabla_Registro_Tareas1[Actividad], 0)),Indice_PROBLAM_Aux_Estado_Desarrollo,Indice_PROBLAM_Aux_Estado_SinIniciar) -> Sin iniciar | Q30: =IF(P30<>"",1+INT((Tabla_Plan_Actividad[[#This Row],[Fecha de fin Ideal]]-Indice_Plan_FechaInicio)/7),) -> 0 | R30: {=IF(plan!$N30<>Indice_PROBLAM_Aux_Estado_SinIniciar,INDEX(cronograma!$F$4:$AN$4,1,_xlfn.XMATCH(TRUE,cronograma!$F32:$AN32<>0,0)),Indice_Aux_SinFecha)} -> × | S30: {=IF(plan!$N30=Indice_PROBLAM_Aux_Estado_Finalizada,INDEX(cronograma!$F$4:$AL$4,1,_xlfn.XMATCH(TRUE,cronograma!$F32:$AL32<>0,0,-1)),Indice_Aux_SinFecha)} -> × | T30: {=IF(S30<>Indice_Aux_SinFecha,1+INT((Tabla_Plan_Actividad[[#This Row],[Fecha de fin Real]]-Indice_Plan_FechaInicio)/7),)} -> 0 | U30: =SUMIFS(Tabla_Registro_Tareas_Agregada[Minutos],Tabla_Registro_Tareas_Agregada[Actividad],plan!$C30)/60 -> 0
B31: 31 | I31: =Tabla_Plan_Actividad[[#This Row],[LPs individuales]]*Indice_PROBLAM_NumEstudiantes -> 0 | L31: =IF(K31<>"",1+INT((Tabla_Plan_Actividad[[#This Row],[Fecha de fin Plan]]-Indice_Plan_FechaInicio)/7),) -> 0 | N31: =IF(ISNUMBER(MATCH(plan!$C31, Tabla_Registro_Tareas1[Actividad], 0)),Indice_PROBLAM_Aux_Estado_Desarrollo,Indice_PROBLAM_Aux_Estado_SinIniciar) -> Sin iniciar | Q31: =IF(P31<>"",1+INT((Tabla_Plan_Actividad[[#This Row],[Fecha de fin Ideal]]-Indice_Plan_FechaInicio)/7),) -> 0 | R31: {=IF(plan!$N31<>Indice_PROBLAM_Aux_Estado_SinIniciar,INDEX(cronograma!$F$4:$AN$4,1,_xlfn.XMATCH(TRUE,cronograma!$F33:$AN33<>0,0)),Indice_Aux_SinFecha)} -> × | S31: {=IF(plan!$N31=Indice_PROBLAM_Aux_Estado_Finalizada,INDEX(cronograma!$F$4:$AL$4,1,_xlfn.XMATCH(TRUE,cronograma!$F33:$AL33<>0,0,-1)),Indice_Aux_SinFecha)} -> × | T31: {=IF(S31<>Indice_Aux_SinFecha,1+INT((Tabla_Plan_Actividad[[#This Row],[Fecha de fin Real]]-Indice_Plan_FechaInicio)/7),)} -> 0 | U31: =SUMIFS(Tabla_Registro_Tareas_Agregada[Minutos],Tabla_Registro_Tareas_Agregada[Actividad],plan!$C31)/60 -> 0
B32: 32 | I32: =Tabla_Plan_Actividad[[#This Row],[LPs individuales]]*Indice_PROBLAM_NumEstudiantes -> 0 | L32: =IF(K32<>"",1+INT((Tabla_Plan_Actividad[[#This Row],[Fecha de fin Plan]]-Indice_Plan_FechaInicio)/7),) -> 0 | N32: =IF(ISNUMBER(MATCH(plan!$C32, Tabla_Registro_Tareas1[Actividad], 0)),Indice_PROBLAM_Aux_Estado_Desarrollo,Indice_PROBLAM_Aux_Estado_SinIniciar) -> Sin iniciar | Q32: =IF(P32<>"",1+INT((Tabla_Plan_Actividad[[#This Row],[Fecha de fin Ideal]]-Indice_Plan_FechaInicio)/7),) -> 0 | R32: {=IF(plan!$N32<>Indice_PROBLAM_Aux_Estado_SinIniciar,INDEX(cronograma!$F$4:$AN$4,1,_xlfn.XMATCH(TRUE,cronograma!$F34:$AN34<>0,0)),Indice_Aux_SinFecha)} -> × | S32: {=IF(plan!$N32=Indice_PROBLAM_Aux_Estado_Finalizada,INDEX(cronograma!$F$4:$AL$4,1,_xlfn.XMATCH(TRUE,cronograma!$F34:$AL34<>0,0,-1)),Indice_Aux_SinFecha)} -> × | T32: {=IF(S32<>Indice_Aux_SinFecha,1+INT((Tabla_Plan_Actividad[[#This Row],[Fecha de fin Real]]-Indice_Plan_FechaInicio)/7),)} -> 0 | U32: =SUMIFS(Tabla_Registro_Tareas_Agregada[Minutos],Tabla_Registro_Tareas_Agregada[Actividad],plan!$C32)/60 -> 0
B33: 33 | I33: =Tabla_Plan_Actividad[[#This Row],[LPs individuales]]*Indice_PROBLAM_NumEstudiantes -> 0 | L33: =IF(K33<>"",1+INT((Tabla_Plan_Actividad[[#This Row],[Fecha de fin Plan]]-Indice_Plan_FechaInicio)/7),) -> 0 | N33: =IF(ISNUMBER(MATCH(plan!$C33, Tabla_Registro_Tareas1[Actividad], 0)),Indice_PROBLAM_Aux_Estado_Desarrollo,Indice_PROBLAM_Aux_Estado_SinIniciar) -> Sin iniciar | Q33: =IF(P33<>"",1+INT((Tabla_Plan_Actividad[[#This Row],[Fecha de fin Ideal]]-Indice_Plan_FechaInicio)/7),) -> 0 | R33: {=IF(plan!$N33<>Indice_PROBLAM_Aux_Estado_SinIniciar,INDEX(cronograma!$F$4:$AN$4,1,_xlfn.XMATCH(TRUE,cronograma!$F35:$AN35<>0,0)),Indice_Aux_SinFecha)} -> × | S33: {=IF(plan!$N33=Indice_PROBLAM_Aux_Estado_Finalizada,INDEX(cronograma!$F$4:$AL$4,1,_xlfn.XMATCH(TRUE,cronograma!$F35:$AL35<>0,0,-1)),Indice_Aux_SinFecha)} -> × | T33: {=IF(S33<>Indice_Aux_SinFecha,1+INT((Tabla_Plan_Actividad[[#This Row],[Fecha de fin Real]]-Indice_Plan_FechaInicio)/7),)} -> 0 | U33: =SUMIFS(Tabla_Registro_Tareas_Agregada[Minutos],Tabla_Registro_Tareas_Agregada[Actividad],plan!$C33)/60 -> 0
B34: 34 | I34: =Tabla_Plan_Actividad[[#This Row],[LPs individuales]]*Indice_PROBLAM_NumEstudiantes -> 0 | L34: =IF(K34<>"",1+INT((Tabla_Plan_Actividad[[#This Row],[Fecha de fin Plan]]-Indice_Plan_FechaInicio)/7),) -> 0 | N34: =IF(ISNUMBER(MATCH(plan!$C34, Tabla_Registro_Tareas1[Actividad], 0)),Indice_PROBLAM_Aux_Estado_Desarrollo,Indice_PROBLAM_Aux_Estado_SinIniciar) -> Sin iniciar | Q34: =IF(P34<>"",1+INT((Tabla_Plan_Actividad[[#This Row],[Fecha de fin Ideal]]-Indice_Plan_FechaInicio)/7),) -> 0 | R34: {=IF(plan!$N34<>Indice_PROBLAM_Aux_Estado_SinIniciar,INDEX(cronograma!$F$4:$AN$4,1,_xlfn.XMATCH(TRUE,cronograma!$F36:$AN36<>0,0)),Indice_Aux_SinFecha)} -> × | S34: {=IF(plan!$N34=Indice_PROBLAM_Aux_Estado_Finalizada,INDEX(cronograma!$F$4:$AL$4,1,_xlfn.XMATCH(TRUE,cronograma!$F36:$AL36<>0,0,-1)),Indice_Aux_SinFecha)} -> × | T34: {=IF(S34<>Indice_Aux_SinFecha,1+INT((Tabla_Plan_Actividad[[#This Row],[Fecha de fin Real]]-Indice_Plan_FechaInicio)/7),)} -> 0 | U34: =SUMIFS(Tabla_Registro_Tareas_Agregada[Minutos],Tabla_Registro_Tareas_Agregada[Actividad],plan!$C34)/60 -> 0
B35: 35 | I35: =Tabla_Plan_Actividad[[#This Row],[LPs individuales]]*Indice_PROBLAM_NumEstudiantes -> 0 | L35: =IF(K35<>"",1+INT((Tabla_Plan_Actividad[[#This Row],[Fecha de fin Plan]]-Indice_Plan_FechaInicio)/7),) -> 0 | N35: =IF(ISNUMBER(MATCH(plan!$C35, Tabla_Registro_Tareas1[Actividad], 0)),Indice_PROBLAM_Aux_Estado_Desarrollo,Indice_PROBLAM_Aux_Estado_SinIniciar) -> Sin iniciar | Q35: =IF(P35<>"",1+INT((Tabla_Plan_Actividad[[#This Row],[Fecha de fin Ideal]]-Indice_Plan_FechaInicio)/7),) -> 0 | R35: {=IF(plan!$N35<>Indice_PROBLAM_Aux_Estado_SinIniciar,INDEX(cronograma!$F$4:$AN$4,1,_xlfn.XMATCH(TRUE,cronograma!$F37:$AN37<>0,0)),Indice_Aux_SinFecha)} -> × | S35: {=IF(plan!$N35=Indice_PROBLAM_Aux_Estado_Finalizada,INDEX(cronograma!$F$4:$AL$4,1,_xlfn.XMATCH(TRUE,cronograma!$F37:$AL37<>0,0,-1)),Indice_Aux_SinFecha)} -> × | T35: {=IF(S35<>Indice_Aux_SinFecha,1+INT((Tabla_Plan_Actividad[[#This Row],[Fecha de fin Real]]-Indice_Plan_FechaInicio)/7),)} -> 0 | U35: =SUMIFS(Tabla_Registro_Tareas_Agregada[Minutos],Tabla_Registro_Tareas_Agregada[Actividad],plan!$C35)/60 -> 0
... B46: 46 | I46: =Tabla_Plan_Actividad[[#This Row],[LPs individuales]]*Indice_PROBLAM_NumEstudiantes -> 0 | L46: =IF(K46<>"",1+INT((Tabla_Plan_Actividad[[#This Row],[Fecha de fin Plan]]-Indice_Plan_FechaInicio)/7),) -> 0 | N46: =IF(ISNUMBER(MATCH(plan!$C46, Tabla_Registro_Tareas1[Actividad], 0)),Indice_PROBLAM_Aux_Estado_Desarrollo,Indice_PROBLAM_Aux_Estado_SinIniciar) -> Sin iniciar | Q46: =IF(P46<>"",1+INT((Tabla_Plan_Actividad[[#This Row],[Fecha de fin Ideal]]-Indice_Plan_FechaInicio)/7),) -> 0 | R46: {=IF(plan!$N46<>Indice_PROBLAM_Aux_Estado_SinIniciar,INDEX(cronograma!$F$4:$AN$4,1,_xlfn.XMATCH(TRUE,cronograma!$F48:$AN48<>0,0)),Indice_Aux_SinFecha)} -> × | S46: {=IF(plan!$N46=Indice_PROBLAM_Aux_Estado_Finalizada,INDEX(cronograma!$F$4:$AL$4,1,_xlfn.XMATCH(TRUE,cronograma!$F48:$AL48<>0,0,-1)),Indice_Aux_SinFecha)} -> × | T46: {=IF(S46<>Indice_Aux_SinFecha,1+INT((Tabla_Plan_Actividad[[#This Row],[Fecha de fin Real]]-Indice_Plan_FechaInicio)/7),)} -> 0 | U46: =SUMIFS(Tabla_Registro_Tareas_Agregada[Minutos],Tabla_Registro_Tareas_Agregada[Actividad],plan!$C46)/60 -> 0
B47: 47 | C47: Ficticia #1 | D47: Ciclo de vida | E47: Ficticia #1 | I47: =Tabla_Plan_Actividad[[#This Row],[LPs individuales]]*Indice_PROBLAM_NumEstudiantes -> 0 | J47: 46056 | K47: =Tabla_Plan_Actividad[[#This Row],[Fecha de inicio Plan]] -> 46056 | L47: 1 | M47: =Tabla_Plan_Actividad[[#This Row],[Fecha de fin Plan]] -> 46056 | N47: Sin iniciar | Q47: =IF(P47<>"",1+INT((Tabla_Plan_Actividad[[#This Row],[Fecha de fin Ideal]]-Indice_Plan_FechaInicio)/7),) -> 0 | R47: {=IF(plan!$N47<>Indice_PROBLAM_Aux_Estado_SinIniciar,INDEX(cronograma!$F$4:$AN$4,1,_xlfn.XMATCH(TRUE,cronograma!$F49:$AN49<>0,0)),Indice_Aux_SinFecha)} -> × | S47: {=IF(plan!$N47=Indice_PROBLAM_Aux_Estado_Finalizada,INDEX(cronograma!$F$4:$AL$4,1,_xlfn.XMATCH(TRUE,cronograma!$F49:$AL49<>0,0,-1)),Indice_Aux_SinFecha)} -> × | T47: {=IF(S47<>Indice_Aux_SinFecha,1+INT((Tabla_Plan_Actividad[[#This Row],[Fecha de fin Real]]-Indice_Plan_FechaInicio)/7),)} -> 0 | U47: =SUMIFS(Tabla_Registro_Tareas_Agregada[Minutos],Tabla_Registro_Tareas_Agregada[Actividad],plan!$C47)/60 -> 0
B48: 48 | C48: Ficticia #2 | D48: Ingeniería de datos | E48: Ficticia #2 | I48: =Tabla_Plan_Actividad[[#This Row],[LPs individuales]]*Indice_PROBLAM_NumEstudiantes -> 0 | J48: 46056 | K48: =Tabla_Plan_Actividad[[#This Row],[Fecha de inicio Plan]] -> 46056 | L48: 1 | M48: =Tabla_Plan_Actividad[[#This Row],[Fecha de fin Plan]] -> 46056 | N48: =IF(ISNUMBER(MATCH(plan!$C48, Tabla_Registro_Tareas1[Actividad], 0)),Indice_PROBLAM_Aux_Estado_Desarrollo,Indice_PROBLAM_Aux_Estado_SinIniciar) -> Sin iniciar | Q48: =IF(P48<>"",1+INT((Tabla_Plan_Actividad[[#This Row],[Fecha de fin Ideal]]-Indice_Plan_FechaInicio)/7),) -> 0 | R48: {=IF(plan!$N48<>Indice_PROBLAM_Aux_Estado_SinIniciar,INDEX(cronograma!$F$4:$AN$4,1,_xlfn.XMATCH(TRUE,cronograma!$F50:$AN50<>0,0)),Indice_Aux_SinFecha)} -> × | S48: {=IF(plan!$N48=Indice_PROBLAM_Aux_Estado_Finalizada,INDEX(cronograma!$F$4:$AL$4,1,_xlfn.XMATCH(TRUE,cronograma!$F50:$AL50<>0,0,-1)),Indice_Aux_SinFecha)} -> × | T48: {=IF(S48<>Indice_Aux_SinFecha,1+INT((Tabla_Plan_Actividad[[#This Row],[Fecha de fin Real]]-Indice_Plan_FechaInicio)/7),)} -> 0 | U48: =SUMIFS(Tabla_Registro_Tareas_Agregada[Minutos],Tabla_Registro_Tareas_Agregada[Actividad],plan!$C48)/60 -> 0
B49: 49 | C49: Ficticia #3 | D49: Diseño físico | E49: Ficticia #3 | I49: =Tabla_Plan_Actividad[[#This Row],[LPs individuales]]*Indice_PROBLAM_NumEstudiantes -> 0 | J49: 46056 | K49: =Tabla_Plan_Actividad[[#This Row],[Fecha de inicio Plan]] -> 46056 | L49: 1 | M49: =Tabla_Plan_Actividad[[#This Row],[Fecha de fin Plan]] -> 46056 | N49: =IF(ISNUMBER(MATCH(plan!$C49, Tabla_Registro_Tareas1[Actividad], 0)),Indice_PROBLAM_Aux_Estado_Desarrollo,Indice_PROBLAM_Aux_Estado_SinIniciar) -> Sin iniciar | Q49: =IF(P49<>"",1+INT((Tabla_Plan_Actividad[[#This Row],[Fecha de fin Ideal]]-Indice_Plan_FechaInicio)/7),) -> 0 | R49: {=IF(plan!$N49<>Indice_PROBLAM_Aux_Estado_SinIniciar,INDEX(cronograma!$F$4:$AN$4,1,_xlfn.XMATCH(TRUE,cronograma!$F51:$AN51<>0,0)),Indice_Aux_SinFecha)} -> × | S49: {=IF(plan!$N49=Indice_PROBLAM_Aux_Estado_Finalizada,INDEX(cronograma!$F$4:$AL$4,1,_xlfn.XMATCH(TRUE,cronograma!$F51:$AL51<>0,0,-1)),Indice_Aux_SinFecha)} -> × | T49: {=IF(S49<>Indice_Aux_SinFecha,1+INT((Tabla_Plan_Actividad[[#This Row],[Fecha de fin Real]]-Indice_Plan_FechaInicio)/7),)} -> 0 | U49: =SUMIFS(Tabla_Registro_Tareas_Agregada[Minutos],Tabla_Registro_Tareas_Agregada[Actividad],plan!$C49)/60 -> 0
B50: 50 | C50: Ficticia #4 | D50: Equipo | E50: Ficticia #4 | I50: =Tabla_Plan_Actividad[[#This Row],[LPs individuales]]*Indice_PROBLAM_NumEstudiantes -> 0 | J50: 46056 | K50: =Tabla_Plan_Actividad[[#This Row],[Fecha de inicio Plan]] -> 46056 | L50: 1 | M50: =Tabla_Plan_Actividad[[#This Row],[Fecha de fin Plan]] -> 46056 | N50: =IF(ISNUMBER(MATCH(plan!$C50, Tabla_Registro_Tareas1[Actividad], 0)),Indice_PROBLAM_Aux_Estado_Desarrollo,Indice_PROBLAM_Aux_Estado_SinIniciar) -> Sin iniciar | Q50: =IF(P50<>"",1+INT((Tabla_Plan_Actividad[[#This Row],[Fecha de fin Ideal]]-Indice_Plan_FechaInicio)/7),) -> 0 | R50: {=IF(plan!$N50<>Indice_PROBLAM_Aux_Estado_SinIniciar,INDEX(cronograma!$F$4:$AN$4,1,_xlfn.XMATCH(TRUE,cronograma!$F52:$AN52<>0,0)),Indice_Aux_SinFecha)} -> × | S50: {=IF(plan!$N50=Indice_PROBLAM_Aux_Estado_Finalizada,INDEX(cronograma!$F$4:$AL$4,1,_xlfn.XMATCH(TRUE,cronograma!$F52:$AL52<>0,0,-1)),Indice_Aux_SinFecha)} -> × | T50: {=IF(S50<>Indice_Aux_SinFecha,1+INT((Tabla_Plan_Actividad[[#This Row],[Fecha de fin Real]]-Indice_Plan_FechaInicio)/7),)} -> 0 | U50: =SUMIFS(Tabla_Registro_Tareas_Agregada[Minutos],Tabla_Registro_Tareas_Agregada[Actividad],plan!$C50)/60 -> 0
B51: 51 | C51: Ficticia #5 | D51: Gestión de transacciones | E51: Ficticia #5 | I51: =Tabla_Plan_Actividad[[#This Row],[LPs individuales]]*Indice_PROBLAM_NumEstudiantes -> 0 | J51: 46056 | K51: =Tabla_Plan_Actividad[[#This Row],[Fecha de inicio Plan]] -> 46056 | L51: 1 | M51: =Tabla_Plan_Actividad[[#This Row],[Fecha de fin Plan]] -> 46056 | N51: =IF(ISNUMBER(MATCH(plan!$C51, Tabla_Registro_Tareas1[Actividad], 0)),Indice_PROBLAM_Aux_Estado_Desarrollo,Indice_PROBLAM_Aux_Estado_SinIniciar) -> Sin iniciar | Q51: =IF(P51<>"",1+INT((Tabla_Plan_Actividad[[#This Row],[Fecha de fin Ideal]]-Indice_Plan_FechaInicio)/7),) -> 0 | R51: {=IF(plan!$N51<>Indice_PROBLAM_Aux_Estado_SinIniciar,INDEX(cronograma!$F$4:$AN$4,1,_xlfn.XMATCH(TRUE,cronograma!$F53:$AN53<>0,0)),Indice_Aux_SinFecha)} -> × | S51: {=IF(plan!$N51=Indice_PROBLAM_Aux_Estado_Finalizada,INDEX(cronograma!$F$4:$AL$4,1,_xlfn.XMATCH(TRUE,cronograma!$F53:$AL53<>0,0,-1)),Indice_Aux_SinFecha)} -> × | T51: {=IF(S51<>Indice_Aux_SinFecha,1+INT((Tabla_Plan_Actividad[[#This Row],[Fecha de fin Real]]-Indice_Plan_FechaInicio)/7),)} -> 0 | U51: =SUMIFS(Tabla_Registro_Tareas_Agregada[Minutos],Tabla_Registro_Tareas_Agregada[Actividad],plan!$C51)/60 -> 0
...

Sheet cronograma
C2: =problam!B23 -> Sprint #2 | D2: Learning Points | E2: Esfuerzo (horas) | F2: Semana #1 | M2: Semana #2 | T2: Semana #3 | AA2: Semana #4 | AH2: Semana #5 | AO2: Semana #6
D4: =Tabla_Plan_Actividad[[#Totals],[Learning Points]] -> 360 | E4: =Tabla_Plan_Actividad[[#Totals],[Horas de trabajo]] -> 0 | F4: =problam!B24 -> 46097 | G4: =F4+1 -> 46098 | H4: =G4+1 -> 46099 | I4: =H4+1 -> 46100 | J4: =I4+1 -> 46101 | K4: =J4+1 -> 46102 | L4: =K4+1 -> 46103 | M4: =L4+1 -> 46104 | N4: =M4+1 -> 46105 | ... AU4: =AT4+1 -> 46138
B5: =plan!B4 -> 4 | C5: =plan!C4 -> Comprensión del pliego técnico | D5: {=INDEX(plan!$I:$I, $B5)} -> 20 | E5: {=INDEX(plan!$U:$U, $B5)} -> 0 | F5: {=IF(AND(F$4>=INDEX(plan!$J:$J, $B5), F$4<=INDEX(plan!$K:$K, $B5)),1,0)} -> 1 | G5: {=IF(AND(G$4>=INDEX(plan!$J:$J, $B5), G$4<=INDEX(plan!$K:$K, $B5)),1,0)} -> 1 | H5: {=IF(AND(H$4>=INDEX(plan!$J:$J, $B5), H$4<=INDEX(plan!$K:$K, $B5)),1,0)} -> 1 | I5: {=IF(AND(I$4>=INDEX(plan!$J:$J, $B5), I$4<=INDEX(plan!$K:$K, $B5)),1,0)} -> 1 | J5: {=IF(AND(J$4>=INDEX(plan!$J:$J, $B5), J$4<=INDEX(plan!$K:$K, $B5)),1,0)} -> 0 | K5: {=IF(AND(K$4>=INDEX(plan!$J:$J, $B5), K$4<=INDEX(plan!$K:$K, $B5)),1,0)} -> 0 | L5: {=IF(AND(L$4>=INDEX(plan!$J:$J, $B5), L$4<=INDEX(plan!$K:$K, $B5)),1,0)} -> 0 | M5: {=IF(AND(M$4>=INDEX(plan!$J:$J, $B5), M$4<=INDEX(plan!$K:$K, $B5)),1,0)} -> 0 | ... AU5: {=IF(AND(AU$4>=INDEX(plan!$J:$J, $B5), AU$4<=INDEX(plan!$K:$K, $B5)),1,0)} -> 0
F6: {=_xlfn.LET( _xlpm.act, cronograma!$C5, _xlpm.fecha, cronograma!F$4, _xlpm.ini, INDEX(plan!$J:$J, $B5), _xlpm.fin, INDEX(plan!$K:$K, $B5), _xlpm.existe, COUNTIFS( Tabla_Registro_Tareas_Agregada[Actividad], _xlpm.act, Tabla_Registro_Tareas_Agregada[Fecha], _xlpm.fecha ), IF(_xlpm.existe=0, 0, IF(AND(_xlpm.fecha>=_xlpm.ini, _xlpm.fecha<=_xlpm.fin), 1, -1)) )} -> 0 | G6: {=_xlfn.LET( _xlpm.act, cronograma!$C5, _xlpm.fecha, cronograma!G$4, _xlpm.ini, INDEX(plan!$J:$J, $B5), _xlpm.fin, INDEX(plan!$K:$K, $B5), _xlpm.existe, COUNTIFS( Tabla_Registro_Tareas_Agregada[Actividad], _xlpm.act, Tabla_Registro_Tareas_Agregada[Fecha], _xlpm.fecha ), IF(_xlpm.existe=0, 0, IF(AND(_xlpm.fecha>=_xlpm.ini, _xlpm.fecha<=_xlpm.fin), 1, -1)) )} -> 0 | H6: {=_xlfn.LET( _xlpm.act, cronograma!$C5, _xlpm.fecha, cronograma!H$4, _xlpm.ini, INDEX(plan!$J:$J, $B5), _xlpm.fin, INDEX(plan!$K:$K, $B5), _xlpm.existe, COUNTIFS( Tabla_Registro_Tareas_Agregada[Actividad], _xlpm.act, Tabla_Registro_Tareas_Agregada[Fecha], _xlpm.fecha ), IF(_xlpm.existe=0, 0, IF(AND(_xlpm.fecha>=_xlpm.ini, _xlpm.fecha<=_xlpm.fin), 1, -1)) )} -> 0 | I6: {=_xlfn.LET( _xlpm.act, cronograma!$C5, _xlpm.fecha, cronograma!I$4, _xlpm.ini, INDEX(plan!$J:$J, $B5), _xlpm.fin, INDEX(plan!$K:$K, $B5), _xlpm.existe, COUNTIFS( Tabla_Registro_Tareas_Agregada[Actividad], _xlpm.act, Tabla_Registro_Tareas_Agregada[Fecha], _xlpm.fecha ), IF(_xlpm.existe=0, 0, IF(AND(_xlpm.fecha>=_xlpm.ini, _xlpm.fecha<=_xlpm.fin), 1, -1)) )} -> 0 | J6: {=_xlfn.LET( _xlpm.act, cronograma!$C5, _xlpm.fecha, cronograma!J$4, _xlpm.ini, INDEX(plan!$J:$J, $B5), _xlpm.fin, INDEX(plan!$K:$K, $B5), _xlpm.existe, COUNTIFS( Tabla_Registro_Tareas_Agregada[Actividad], _xlpm.act, Tabla_Registro_Tareas_Agregada[Fecha], _xlpm.fecha ), IF(_xlpm.existe=0, 0, IF(AND(_xlpm.fecha>=_xlpm.ini, _xlpm.fecha<=_xlpm.fin), 1, -1)) )} -> 0 | K6: {=_xlfn.LET( _xlpm.act, cronograma!$C5, _xlpm.fecha, cronograma!K$4, _xlpm.ini, INDEX(plan!$J:$J, $B5), _xlpm.fin, INDEX(plan!$K:$K, $B5), _xlpm.existe, COUNTIFS( Tabla_Registro_Tareas_Agregada[Actividad], _xlpm.act, Tabla_Registro_Tareas_Agregada[Fecha], _xlpm.fecha ), IF(_xlpm.existe=0, 0, IF(AND(_xlpm.fecha>=_xlpm.ini, _xlpm.fecha<=_xlpm.fin), 1, -1)) )} -> 0 | L6: {=_xlfn.LET( _xlpm.act, cronograma!$C5, _xlpm.fecha, cronograma!L$4, _xlpm.ini, INDEX(plan!$J:$J, $B5), _xlpm.fin, INDEX(plan!$K:$K, $B5), _xlpm.existe, COUNTIFS( Tabla_Registro_Tareas_Agregada[Actividad], _xlpm.act, Tabla_Registro_Tareas_Agregada[Fecha], _xlpm.fecha ), IF(_xlpm.existe=0, 0, IF(AND(_xlpm.fecha>=_xlpm.ini, _xlpm.fecha<=_xlpm.fin), 1, -1)) )} -> 0 | M6: {=_xlfn.LET( _xlpm.act, cronograma!$C5, _xlpm.fecha, cronograma!M$4, _xlpm.ini, INDEX(plan!$J:$J, $B5), _xlpm.fin, INDEX(plan!$K:$K, $B5), _xlpm.existe, COUNTIFS( Tabla_Registro_Tareas_Agregada[Actividad], _xlpm.act, Tabla_Registro_Tareas_Agregada[Fecha], _xlpm.fecha ), IF(_xlpm.existe=0, 0, IF(AND(_xlpm.fecha>=_xlpm.ini, _xlpm.fecha<=_xlpm.fin), 1, -1)) )} -> 0 | ... AU6: {=_xlfn.LET( _xlpm.act, cronograma!$C5, _xlpm.fecha, cronograma!AU$4, _xlpm.ini, INDEX(plan!$J:$J, $B5), _xlpm.fin, INDEX(plan!$K:$K, $B5), _xlpm.existe, COUNTIFS( Tabla_Registro_Tareas_Agregada[Actividad], _xlpm.act, Tabla_Registro_Tareas_Agregada[Fecha], _xlpm.fecha ), IF(_xlpm.existe=0, 0, IF(AND(_xlpm.fecha>=_xlpm.ini, _xlpm.fecha<=_xlpm.fin), 1, -1)) )} -> 0
B7: =plan!B5 -> 5 | C7: =plan!C5 -> Reunión de inicio | D7: {=INDEX(plan!$I:$I, $B7)} -> 15 | E7: {=INDEX(plan!$U:$U, $B7)} -> 0 | F7: {=IF(AND(F$4>=INDEX(plan!$J:$J, $B7), F$4<=INDEX(plan!$K:$K, $B7)),1,0)} -> 0 | G7: {=IF(AND(G$4>=INDEX(plan!$J:$J, $B7), G$4<=INDEX(plan!$K:$K, $B7)),1,0)} -> 0 | H7: {=IF(AND(H$4>=INDEX(plan!$J:$J, $B7), H$4<=INDEX(plan!$K:$K, $B7)),1,0)} -> 0 | I7: {=IF(AND(I$4>=INDEX(plan!$J:$J, $B7), I$4<=INDEX(plan!$K:$K, $B7)),1,0)} -> 1 | J7: {=IF(AND(J$4>=INDEX(plan!$J:$J, $B7), J$4<=INDEX(plan!$K:$K, $B7)),1,0)} -> 1 | K7: {=IF(AND(K$4>=INDEX(plan!$J:$J, $B7), K$4<=INDEX(plan!$K:$K, $B7)),1,0)} -> 0 | L7: {=IF(AND(L$4>=INDEX(plan!$J:$J, $B7), L$4<=INDEX(plan!$K:$K, $B7)),1,0)} -> 0 | M7: {=IF(AND(M$4>=INDEX(plan!$J:$J, $B7), M$4<=INDEX(plan!$K:$K, $B7)),1,0)} -> 0 | ... AU7: {=IF(AND(AU$4>=INDEX(plan!$J:$J, $B7), AU$4<=INDEX(plan!$K:$K, $B7)),1,0)} -> 0
F8: {=_xlfn.LET( _xlpm.act, cronograma!$C7, _xlpm.fecha, cronograma!F$4, _xlpm.ini, INDEX(plan!$J:$J, $B7), _xlpm.fin, INDEX(plan!$K:$K, $B7), _xlpm.existe, COUNTIFS( Tabla_Registro_Tareas_Agregada[Actividad], _xlpm.act, Tabla_Registro_Tareas_Agregada[Fecha], _xlpm.fecha ), IF(_xlpm.existe=0, 0, IF(AND(_xlpm.fecha>=_xlpm.ini, _xlpm.fecha<=_xlpm.fin), 1, -1)) )} -> 0 | G8: {=_xlfn.LET( _xlpm.act, cronograma!$C7, _xlpm.fecha, cronograma!G$4, _xlpm.ini, INDEX(plan!$J:$J, $B7), _xlpm.fin, INDEX(plan!$K:$K, $B7), _xlpm.existe, COUNTIFS( Tabla_Registro_Tareas_Agregada[Actividad], _xlpm.act, Tabla_Registro_Tareas_Agregada[Fecha], _xlpm.fecha ), IF(_xlpm.existe=0, 0, IF(AND(_xlpm.fecha>=_xlpm.ini, _xlpm.fecha<=_xlpm.fin), 1, -1)) )} -> 0 | H8: {=_xlfn.LET( _xlpm.act, cronograma!$C7, _xlpm.fecha, cronograma!H$4, _xlpm.ini, INDEX(plan!$J:$J, $B7), _xlpm.fin, INDEX(plan!$K:$K, $B7), _xlpm.existe, COUNTIFS( Tabla_Registro_Tareas_Agregada[Actividad], _xlpm.act, Tabla_Registro_Tareas_Agregada[Fecha], _xlpm.fecha ), IF(_xlpm.existe=0, 0, IF(AND(_xlpm.fecha>=_xlpm.ini, _xlpm.fecha<=_xlpm.fin), 1, -1)) )} -> 0 | I8: {=_xlfn.LET( _xlpm.act, cronograma!$C7, _xlpm.fecha, cronograma!I$4, _xlpm.ini, INDEX(plan!$J:$J, $B7), _xlpm.fin, INDEX(plan!$K:$K, $B7), _xlpm.existe, COUNTIFS( Tabla_Registro_Tareas_Agregada[Actividad], _xlpm.act, Tabla_Registro_Tareas_Agregada[Fecha], _xlpm.fecha ), IF(_xlpm.existe=0, 0, IF(AND(_xlpm.fecha>=_xlpm.ini, _xlpm.fecha<=_xlpm.fin), 1, -1)) )} -> 0 | J8: {=_xlfn.LET( _xlpm.act, cronograma!$C7, _xlpm.fecha, cronograma!J$4, _xlpm.ini, INDEX(plan!$J:$J, $B7), _xlpm.fin, INDEX(plan!$K:$K, $B7), _xlpm.existe, COUNTIFS( Tabla_Registro_Tareas_Agregada[Actividad], _xlpm.act, Tabla_Registro_Tareas_Agregada[Fecha], _xlpm.fecha ), IF(_xlpm.existe=0, 0, IF(AND(_xlpm.fecha>=_xlpm.ini, _xlpm.fecha<=_xlpm.fin), 1, -1)) )} -> 0 | K8: {=_xlfn.LET( _xlpm.act, cronograma!$C7, _xlpm.fecha, cronograma!K$4, _xlpm.ini, INDEX(plan!$J:$J, $B7), _xlpm.fin, INDEX(plan!$K:$K, $B7), _xlpm.existe, COUNTIFS( Tabla_Registro_Tareas_Agregada[Actividad], _xlpm.act, Tabla_Registro_Tareas_Agregada[Fecha], _xlpm.fecha ), IF(_xlpm.existe=0, 0, IF(AND(_xlpm.fecha>=_xlpm.ini, _xlpm.fecha<=_xlpm.fin), 1, -1)) )} -> 0 | L8: {=_xlfn.LET( _xlpm.act, cronograma!$C7, _xlpm.fecha, cronograma!L$4, _xlpm.ini, INDEX(plan!$J:$J, $B7), _xlpm.fin, INDEX(plan!$K:$K, $B7), _xlpm.existe, COUNTIFS( Tabla_Registro_Tareas_Agregada[Actividad], _xlpm.act, Tabla_Registro_Tareas_Agregada[Fecha], _xlpm.fecha ), IF(_xlpm.existe=0, 0, IF(AND(_xlpm.fecha>=_xlpm.ini, _xlpm.fecha<=_xlpm.fin), 1, -1)) )} -> 0 | M8: {=_xlfn.LET( _xlpm.act, cronograma!$C7, _xlpm.fecha, cronograma!M$4, _xlpm.ini, INDEX(plan!$J:$J, $B7), _xlpm.fin, INDEX(plan!$K:$K, $B7), _xlpm.existe, COUNTIFS( Tabla_Registro_Tareas_Agregada[Actividad], _xlpm.act, Tabla_Registro_Tareas_Agregada[Fecha], _xlpm.fecha ), IF(_xlpm.existe=0, 0, IF(AND(_xlpm.fecha>=_xlpm.ini, _xlpm.fecha<=_xlpm.fin), 1, -1)) )} -> 0 | ... AU8: {=_xlfn.LET( _xlpm.act, cronograma!$C7, _xlpm.fecha, cronograma!AU$4, _xlpm.ini, INDEX(plan!$J:$J, $B7), _xlpm.fin, INDEX(plan!$K:$K, $B7), _xlpm.existe, COUNTIFS( Tabla_Registro_Tareas_Agregada[Actividad], _xlpm.act, Tabla_Registro_Tareas_Agregada[Fecha], _xlpm.fecha ), IF(_xlpm.existe=0, 0, IF(AND(_xlpm.fecha>=_xlpm.ini, _xlpm.fecha<=_xlpm.fin), 1, -1)) )} -> 0
B9: =plan!B6 -> 6 | C9: =plan!C6 -> Gestión de cambios Diccionario | D9: {=INDEX(plan!$I:$I, $B9)} -> 5 | E9: {=INDEX(plan!$U:$U, $B9)} -> 0 | F9: {=IF(AND(F$4>=INDEX(plan!$J:$J, $B9), F$4<=INDEX(plan!$K:$K, $B9)),1,0)} -> 0 | G9: {=IF(AND(G$4>=INDEX(plan!$J:$J, $B9), G$4<=INDEX(plan!$K:$K, $B9)),1,0)} -> 0 | H9: {=IF(AND(H$4>=INDEX(plan!$J:$J, $B9), H$4<=INDEX(plan!$K:$K, $B9)),1,0)} -> 0 | I9: {=IF(AND(I$4>=INDEX(plan!$J:$J, $B9), I$4<=INDEX(plan!$K:$K, $B9)),1,0)} -> 0 | J9: {=IF(AND(J$4>=INDEX(plan!$J:$J, $B9), J$4<=INDEX(plan!$K:$K, $B9)),1,0)} -> 1 | K9: {=IF(AND(K$4>=INDEX(plan!$J:$J, $B9), K$4<=INDEX(plan!$K:$K, $B9)),1,0)} -> 1 | L9: {=IF(AND(L$4>=INDEX(plan!$J:$J, $B9), L$4<=INDEX(plan!$K:$K, $B9)),1,0)} -> 1 | M9: {=IF(AND(M$4>=INDEX(plan!$J:$J, $B9), M$4<=INDEX(plan!$K:$K, $B9)),1,0)} -> 1 | ... AU9: {=IF(AND(AU$4>=INDEX(plan!$J:$J, $B9), AU$4<=INDEX(plan!$K:$K, $B9)),1,0)} -> 0
F10: {=_xlfn.LET( _xlpm.act, cronograma!$C9, _xlpm.fecha, cronograma!F$4, _xlpm.ini, INDEX(plan!$J:$J, $B9), _xlpm.fin, INDEX(plan!$K:$K, $B9), _xlpm.existe, COUNTIFS( Tabla_Registro_Tareas_Agregada[Actividad], _xlpm.act, Tabla_Registro_Tareas_Agregada[Fecha], _xlpm.fecha ), IF(_xlpm.existe=0, 0, IF(AND(_xlpm.fecha>=_xlpm.ini, _xlpm.fecha<=_xlpm.fin), 1, -1)) )} -> 0 | G10: {=_xlfn.LET( _xlpm.act, cronograma!$C9, _xlpm.fecha, cronograma!G$4, _xlpm.ini, INDEX(plan!$J:$J, $B9), _xlpm.fin, INDEX(plan!$K:$K, $B9), _xlpm.existe, COUNTIFS( Tabla_Registro_Tareas_Agregada[Actividad], _xlpm.act, Tabla_Registro_Tareas_Agregada[Fecha], _xlpm.fecha ), IF(_xlpm.existe=0, 0, IF(AND(_xlpm.fecha>=_xlpm.ini, _xlpm.fecha<=_xlpm.fin), 1, -1)) )} -> 0 | H10: {=_xlfn.LET( _xlpm.act, cronograma!$C9, _xlpm.fecha, cronograma!H$4, _xlpm.ini, INDEX(plan!$J:$J, $B9), _xlpm.fin, INDEX(plan!$K:$K, $B9), _xlpm.existe, COUNTIFS( Tabla_Registro_Tareas_Agregada[Actividad], _xlpm.act, Tabla_Registro_Tareas_Agregada[Fecha], _xlpm.fecha ), IF(_xlpm.existe=0, 0, IF(AND(_xlpm.fecha>=_xlpm.ini, _xlpm.fecha<=_xlpm.fin), 1, -1)) )} -> 0 | I10: {=_xlfn.LET( _xlpm.act, cronograma!$C9, _xlpm.fecha, cronograma!I$4, _xlpm.ini, INDEX(plan!$J:$J, $B9), _xlpm.fin, INDEX(plan!$K:$K, $B9), _xlpm.existe, COUNTIFS( Tabla_Registro_Tareas_Agregada[Actividad], _xlpm.act, Tabla_Registro_Tareas_Agregada[Fecha], _xlpm.fecha ), IF(_xlpm.existe=0, 0, IF(AND(_xlpm.fecha>=_xlpm.ini, _xlpm.fecha<=_xlpm.fin), 1, -1)) )} -> 0 | J10: {=_xlfn.LET( _xlpm.act, cronograma!$C9, _xlpm.fecha, cronograma!J$4, _xlpm.ini, INDEX(plan!$J:$J, $B9), _xlpm.fin, INDEX(plan!$K:$K, $B9), _xlpm.existe, COUNTIFS( Tabla_Registro_Tareas_Agregada[Actividad], _xlpm.act, Tabla_Registro_Tareas_Agregada[Fecha], _xlpm.fecha ), IF(_xlpm.existe=0, 0, IF(AND(_xlpm.fecha>=_xlpm.ini, _xlpm.fecha<=_xlpm.fin), 1, -1)) )} -> 0 | K10: {=_xlfn.LET( _xlpm.act, cronograma!$C9, _xlpm.fecha, cronograma!K$4, _xlpm.ini, INDEX(plan!$J:$J, $B9), _xlpm.fin, INDEX(plan!$K:$K, $B9), _xlpm.existe, COUNTIFS( Tabla_Registro_Tareas_Agregada[Actividad], _xlpm.act, Tabla_Registro_Tareas_Agregada[Fecha], _xlpm.fecha ), IF(_xlpm.existe=0, 0, IF(AND(_xlpm.fecha>=_xlpm.ini, _xlpm.fecha<=_xlpm.fin), 1, -1)) )} -> 0 | L10: {=_xlfn.LET( _xlpm.act, cronograma!$C9, _xlpm.fecha, cronograma!L$4, _xlpm.ini, INDEX(plan!$J:$J, $B9), _xlpm.fin, INDEX(plan!$K:$K, $B9), _xlpm.existe, COUNTIFS( Tabla_Registro_Tareas_Agregada[Actividad], _xlpm.act, Tabla_Registro_Tareas_Agregada[Fecha], _xlpm.fecha ), IF(_xlpm.existe=0, 0, IF(AND(_xlpm.fecha>=_xlpm.ini, _xlpm.fecha<=_xlpm.fin), 1, -1)) )} -> 0 | M10: {=_xlfn.LET( _xlpm.act, cronograma!$C9, _xlpm.fecha, cronograma!M$4, _xlpm.ini, INDEX(plan!$J:$J, $B9), _xlpm.fin, INDEX(plan!$K:$K, $B9), _xlpm.existe, COUNTIFS( Tabla_Registro_Tareas_Agregada[Actividad], _xlpm.act, Tabla_Registro_Tareas_Agregada[Fecha], _xlpm.fecha ), IF(_xlpm.existe=0, 0, IF(AND(_xlpm.fecha>=_xlpm.ini, _xlpm.fecha<=_xlpm.fin), 1, -1)) )} -> 0 | ... AU10: {=_xlfn.LET( _xlpm.act, cronograma!$C9, _xlpm.fecha, cronograma!AU$4, _xlpm.ini, INDEX(plan!$J:$J, $B9), _xlpm.fin, INDEX(plan!$K:$K, $B9), _xlpm.existe, COUNTIFS( Tabla_Registro_Tareas_Agregada[Actividad], _xlpm.act, Tabla_Registro_Tareas_Agregada[Fecha], _xlpm.fecha ), IF(_xlpm.existe=0, 0, IF(AND(_xlpm.fecha>=_xlpm.ini, _xlpm.fecha<=_xlpm.fin), 1, -1)) )} -> 0
B11: =plan!B7 -> 7 | C11: =plan!C7 -> Gestión de cambios Integridad | D11: {=INDEX(plan!$I:$I, $B11)} -> 10 | E11: {=INDEX(plan!$U:$U, $B11)} -> 0 | F11: {=IF(AND(F$4>=INDEX(plan!$J:$J, $B11), F$4<=INDEX(plan!$K:$K, $B11)),1,0)} -> 0 | G11: {=IF(AND(G$4>=INDEX(plan!$J:$J, $B11), G$4<=INDEX(plan!$K:$K, $B11)),1,0)} -> 0 | H11: {=IF(AND(H$4>=INDEX(plan!$J:$J, $B11), H$4<=INDEX(plan!$K:$K, $B11)),1,0)} -> 0 | I11: {=IF(AND(I$4>=INDEX(plan!$J:$J, $B11), I$4<=INDEX(plan!$K:$K, $B11)),1,0)} -> 0 | J11: {=IF(AND(J$4>=INDEX(plan!$J:$J, $B11), J$4<=INDEX(plan!$K:$K, $B11)),1,0)} -> 0 | K11: {=IF(AND(K$4>=INDEX(plan!$J:$J, $B11), K$4<=INDEX(plan!$K:$K, $B11)),1,0)} -> 0 | L11: {=IF(AND(L$4>=INDEX(plan!$J:$J, $B11), L$4<=INDEX(plan!$K:$K, $B11)),1,0)} -> 0 | M11: {=IF(AND(M$4>=INDEX(plan!$J:$J, $B11), M$4<=INDEX(plan!$K:$K, $B11)),1,0)} -> 1 | ... AU11: {=IF(AND(AU$4>=INDEX(plan!$J:$J, $B11), AU$4<=INDEX(plan!$K:$K, $B11)),1,0)} -> 0
